[2022-06-10T22:03:05Z] DEBUG    - Logging set up successfully
[2022-06-10T22:03:05Z] DEBUG    - Running test: Namespace(cloudformation_endpoint_url=None, command=<function test at 0x116ad3160>, docker_image=None, endpoint='http://127.0.0.1:3001', enforce_timeout='60', function_name='TypeFunction', log_group_name=None, log_role_arn=None, passed_to_pytest=[], region='us-east-1', role_arn=None, subparser_name='test', verbose=0, version=False)
[2022-06-10T22:03:05Z] DEBUG    - Root directory: /Volumes/workplace/aws-cloudformation-resource-providers-redshiftserverless
[2022-06-10T22:03:05Z] DEBUG    - Loading project file '/Volumes/workplace/aws-cloudformation-resource-providers-redshiftserverless/.rpdk-config'
[2022-06-10T22:03:05Z] DEBUG    - Project file /Volumes/workplace/aws-cloudformation-resource-providers-redshiftserverless/.rpdk-config not found. Have you run 'init' or in a wrong directory?
Traceback (most recent call last):
  File "/Volumes/workplace/python-venv-cfn-migration-dev/lib/python3.8/site-packages/rpdk/core/project.py", line 562, in load
    self.load_settings()
  File "/Volumes/workplace/python-venv-cfn-migration-dev/lib/python3.8/site-packages/rpdk/core/project.py", line 234, in load_settings
    with self.settings_path.open("r", encoding="utf-8") as f:
  File "/Library/Developer/CommandLineTools/Library/Frameworks/Python3.framework/Versions/3.8/lib/python3.8/pathlib.py", line 1213, in open
    return io.open(self, mode, buffering, encoding, errors, newline,
  File "/Library/Developer/CommandLineTools/Library/Frameworks/Python3.framework/Versions/3.8/lib/python3.8/pathlib.py", line 1069, in _opener
    return self._accessor.open(self, flags, mode)
FileNotFoundError: [Errno 2] No such file or directory: '/Volumes/workplace/aws-cloudformation-resource-providers-redshiftserverless/.rpdk-config'
[2022-06-10T22:03:05Z] DEBUG    - Caught exit recommendation
Traceback (most recent call last):
  File "/Volumes/workplace/python-venv-cfn-migration-dev/lib/python3.8/site-packages/rpdk/core/project.py", line 562, in load
    self.load_settings()
  File "/Volumes/workplace/python-venv-cfn-migration-dev/lib/python3.8/site-packages/rpdk/core/project.py", line 234, in load_settings
    with self.settings_path.open("r", encoding="utf-8") as f:
  File "/Library/Developer/CommandLineTools/Library/Frameworks/Python3.framework/Versions/3.8/lib/python3.8/pathlib.py", line 1213, in open
    return io.open(self, mode, buffering, encoding, errors, newline,
  File "/Library/Developer/CommandLineTools/Library/Frameworks/Python3.framework/Versions/3.8/lib/python3.8/pathlib.py", line 1069, in _opener
    return self._accessor.open(self, flags, mode)
FileNotFoundError: [Errno 2] No such file or directory: '/Volumes/workplace/aws-cloudformation-resource-providers-redshiftserverless/.rpdk-config'

The above exception was the direct cause of the following exception:

Traceback (most recent call last):
  File "/Volumes/workplace/python-venv-cfn-migration-dev/lib/python3.8/site-packages/rpdk/core/cli.py", line 100, in main
    args.command(args)
  File "/Volumes/workplace/python-venv-cfn-migration-dev/lib/python3.8/site-packages/rpdk/core/test.py", line 354, in test
    project.load()
  File "/Volumes/workplace/python-venv-cfn-migration-dev/lib/python3.8/site-packages/rpdk/core/project.py", line 564, in load
    self._raise_invalid_project(
  File "/Volumes/workplace/python-venv-cfn-migration-dev/lib/python3.8/site-packages/rpdk/core/project.py", line 229, in _raise_invalid_project
    raise InvalidProjectError(msg) from e
rpdk.core.exceptions.InvalidProjectError: Project file /Volumes/workplace/aws-cloudformation-resource-providers-redshiftserverless/.rpdk-config not found. Have you run 'init' or in a wrong directory?
[2022-06-10T22:03:05Z] CRITICAL - Project file /Volumes/workplace/aws-cloudformation-resource-providers-redshiftserverless/.rpdk-config not found. Have you run 'init' or in a wrong directory?
